(dp1
S'output'
p2
S"<type 'exceptions.IOError'> Unable to create file (unable to open file: name = '~/model.h5', errno = 2, error message = 'No such file or directory', flags = 13, o_flags = 242)"
p3
sS'layer'
p4
S'/home/ria/Desktop/web2py/applications/simpleNN/controllers/default.py'
p5
sS'code'
p6
S'<code object <module> at 0x7f5257c2d1b0, file "/home/ria/Desktop/web2py/applications/simpleNN/controllers/default.py", line 1>'
p7
sS'snapshot'
p8
(dp9
sS'traceback'
p10
S'Traceback (most recent call last):\n  File "/home/ria/Desktop/web2py/gluon/restricted.py", line 219, in restricted\n    exec(ccode, environment)\n  File "/home/ria/Desktop/web2py/applications/simpleNN/controllers/default.py", line 69, in <module>\n  File "/home/ria/Desktop/web2py/gluon/globals.py", line 419, in <lambda>\n    self._caller = lambda f: f()\n  File "/home/ria/Desktop/web2py/applications/simpleNN/controllers/default.py", line 40, in index\n    model.save_weights("~/model.h5")\n  File "/usr/local/lib/python2.7/dist-packages/keras/models.py", line 755, in save_weights\n    f = h5py.File(filepath, \'w\')\n  File "/usr/local/lib/python2.7/dist-packages/h5py/_hl/files.py", line 269, in __init__\n    fid = make_fid(name, mode, userblock_size, fapl, swmr=swmr)\n  File "/usr/local/lib/python2.7/dist-packages/h5py/_hl/files.py", line 105, in make_fid\n    fid = h5f.create(name, h5f.ACC_TRUNC, fapl=fapl, fcpl=fcpl)\n  File "h5py/_objects.pyx", line 54, in h5py._objects.with_phil.wrapper\n  File "h5py/_objects.pyx", line 55, in h5py._objects.with_phil.wrapper\n  File "h5py/h5f.pyx", line 98, in h5py.h5f.create\nIOError: Unable to create file (unable to open file: name = \'~/model.h5\', errno = 2, error message = \'No such file or directory\', flags = 13, o_flags = 242)\n'
p11
s.