(dp1
S'output'
p2
S"<type 'exceptions.AttributeError'> 'Sequential' object has no attribute 'get_default_graph'"
p3
sS'layer'
p4
S'/home/ria/Desktop/web2py/applications/simpleNN/controllers/default.py'
p5
sS'code'
p6
S'<code object <module> at 0x7f6b8a2b7730, file "/home/ria/Desktop/web2py/applications/simpleNN/controllers/default.py", line 1>'
p7
sS'snapshot'
p8
(dp9
sS'traceback'
p10
S'Traceback (most recent call last):\n  File "/home/ria/Desktop/web2py/gluon/restricted.py", line 219, in restricted\n    exec(ccode, environment)\n  File "/home/ria/Desktop/web2py/applications/simpleNN/controllers/default.py", line 87, in <module>\n  File "/home/ria/Desktop/web2py/gluon/globals.py", line 419, in <lambda>\n    self._caller = lambda f: f()\n  File "/home/ria/Desktop/web2py/applications/simpleNN/controllers/default.py", line 35, in index\n    graph = model.get_default_graph()\nAttributeError: \'Sequential\' object has no attribute \'get_default_graph\'\n'
p11
s.